[Config file]: /var/folders/nk/_ysc0b1j4p13gcjtqn0f_8480000gn/T/tmpjeddhag0/0.json
[Unhandled Error] Exception('Maximum number of retries (3) exceeded.')
Traceback (most recent call last):
  File "/Users/neel/fa24_research/search-agents/llms/providers/openai_utils.py", line 53, in wrapper
    return func(*args, **kwargs)
  File "/Users/neel/fa24_research/search-agents/llms/providers/openai_utils.py", line 271, in generate_from_openai_chat_completion
    response = client.chat.completions.create(
  File "/Users/neel/miniconda3/envs/webarena/lib/python3.10/site-packages/openai/_utils/_utils.py", line 299, in wrapper
    return func(*args, **kwargs)
  File "/Users/neel/miniconda3/envs/webarena/lib/python3.10/site-packages/openai/resources/chat/completions.py", line 598, in create
    return self._post(
  File "/Users/neel/miniconda3/envs/webarena/lib/python3.10/site-packages/openai/_base_client.py", line 1063, in post
    return cast(ResponseT, self.request(cast_to, opts, stream=stream, stream_cls=stream_cls))
  File "/Users/neel/miniconda3/envs/webarena/lib/python3.10/site-packages/openai/_base_client.py", line 842, in request
    return self._request(
  File "/Users/neel/miniconda3/envs/webarena/lib/python3.10/site-packages/openai/_base_client.py", line 873, in _request
    return self._retry_request(
  File "/Users/neel/miniconda3/envs/webarena/lib/python3.10/site-packages/openai/_base_client.py", line 933, in _retry_request
    return self._request(
  File "/Users/neel/miniconda3/envs/webarena/lib/python3.10/site-packages/openai/_base_client.py", line 873, in _request
    return self._retry_request(
  File "/Users/neel/miniconda3/envs/webarena/lib/python3.10/site-packages/openai/_base_client.py", line 933, in _retry_request
    return self._request(
  File "/Users/neel/miniconda3/envs/webarena/lib/python3.10/site-packages/openai/_base_client.py", line 885, in _request
    raise self._make_status_error_from_response(err.response) from None
openai.RateLimitError: Error code: 429 - {'error': {'message': 'You exceeded your current quota, please check your plan and billing details. For more information on this error, read the docs: https://platform.openai.com/docs/guides/error-codes/api-errors.', 'type': 'insufficient_quota', 'param': None, 'code': 'insufficient_quota'}}

During handling of the above exception, another exception occurred:

Traceback (most recent call last):
  File "/Users/neel/fa24_research/search-agents/run.py", line 552, in test
    score, new_trajectory, new_action_history, next_actions = take_action_and_score(
  File "/Users/neel/fa24_research/search-agents/run.py", line 487, in take_action_and_score
    next_actions = agent.next_action(
  File "/Users/neel/fa24_research/search-agents/agent/agent.py", line 274, in next_action
    responses = call_llm(lm_config, prompt, num_outputs=max(branching_factor * 2, 20))
  File "/Users/neel/fa24_research/search-agents/llms/utils.py", line 30, in call_llm
    response = generate_from_openai_chat_completion(
  File "/Users/neel/fa24_research/search-agents/llms/providers/openai_utils.py", line 62, in wrapper
    raise Exception(
Exception: Maximum number of retries (3) exceeded.
[Config file]: /var/folders/nk/_ysc0b1j4p13gcjtqn0f_8480000gn/T/tmp4dn69axt/0.json
[Unhandled Error] Exception('Maximum number of retries (3) exceeded.')
Traceback (most recent call last):
  File "/Users/neel/fa24_research/search-agents/llms/providers/openai_utils.py", line 53, in wrapper
    return func(*args, **kwargs)
  File "/Users/neel/fa24_research/search-agents/llms/providers/openai_utils.py", line 271, in generate_from_openai_chat_completion
    response = client.chat.completions.create(
  File "/Users/neel/miniconda3/envs/webarena/lib/python3.10/site-packages/openai/_utils/_utils.py", line 299, in wrapper
    return func(*args, **kwargs)
  File "/Users/neel/miniconda3/envs/webarena/lib/python3.10/site-packages/openai/resources/chat/completions.py", line 598, in create
    return self._post(
  File "/Users/neel/miniconda3/envs/webarena/lib/python3.10/site-packages/openai/_base_client.py", line 1063, in post
    return cast(ResponseT, self.request(cast_to, opts, stream=stream, stream_cls=stream_cls))
  File "/Users/neel/miniconda3/envs/webarena/lib/python3.10/site-packages/openai/_base_client.py", line 842, in request
    return self._request(
  File "/Users/neel/miniconda3/envs/webarena/lib/python3.10/site-packages/openai/_base_client.py", line 873, in _request
    return self._retry_request(
  File "/Users/neel/miniconda3/envs/webarena/lib/python3.10/site-packages/openai/_base_client.py", line 933, in _retry_request
    return self._request(
  File "/Users/neel/miniconda3/envs/webarena/lib/python3.10/site-packages/openai/_base_client.py", line 873, in _request
    return self._retry_request(
  File "/Users/neel/miniconda3/envs/webarena/lib/python3.10/site-packages/openai/_base_client.py", line 933, in _retry_request
    return self._request(
  File "/Users/neel/miniconda3/envs/webarena/lib/python3.10/site-packages/openai/_base_client.py", line 885, in _request
    raise self._make_status_error_from_response(err.response) from None
openai.RateLimitError: Error code: 429 - {'error': {'message': 'You exceeded your current quota, please check your plan and billing details. For more information on this error, read the docs: https://platform.openai.com/docs/guides/error-codes/api-errors.', 'type': 'insufficient_quota', 'param': None, 'code': 'insufficient_quota'}}

During handling of the above exception, another exception occurred:

Traceback (most recent call last):
  File "/Users/neel/fa24_research/search-agents/run.py", line 408, in test
    action = agent.next_action(
  File "/Users/neel/fa24_research/search-agents/agent/agent.py", line 274, in next_action
    responses = call_llm(lm_config, prompt, num_outputs=max(branching_factor * 2, 20))
  File "/Users/neel/fa24_research/search-agents/llms/utils.py", line 30, in call_llm
    response = generate_from_openai_chat_completion(
  File "/Users/neel/fa24_research/search-agents/llms/providers/openai_utils.py", line 62, in wrapper
    raise Exception(
Exception: Maximum number of retries (3) exceeded.
[Config file]: /var/folders/nk/_ysc0b1j4p13gcjtqn0f_8480000gn/T/tmpsjot4x5x/0.json
[Unhandled Error] Error('net::ERR_INTERNET_DISCONNECTED at http://ec2-3-131-244-37.us-east-2.compute.amazonaws.com:7770/\n=========================== logs ===========================\nnavigating to "http://ec2-3-131-244-37.us-east-2.compute.amazonaws.com:7770/", waiting until "load"\n============================================================')
Traceback (most recent call last):
  File "/Users/neel/fa24_research/search-agents/run.py", line 538, in test
    _ = env.reset(options={"config_file": config_file})
  File "/Users/neel/fa24_research/search-agents/browser_env/envs.py", line 248, in reset
    self.setup(config_file=config_file)
  File "/Users/neel/fa24_research/search-agents/browser_env/envs.py", line 203, in setup
    page.goto(url)
  File "/Users/neel/miniconda3/envs/webarena/lib/python3.10/site-packages/playwright/sync_api/_generated.py", line 9303, in goto
    self._sync(
  File "/Users/neel/miniconda3/envs/webarena/lib/python3.10/site-packages/playwright/_impl/_sync_base.py", line 109, in _sync
    return task.result()
  File "/Users/neel/miniconda3/envs/webarena/lib/python3.10/site-packages/playwright/_impl/_page.py", line 479, in goto
    return await self._main_frame.goto(**locals_to_params(locals()))
  File "/Users/neel/miniconda3/envs/webarena/lib/python3.10/site-packages/playwright/_impl/_frame.py", line 147, in goto
    await self._channel.send("goto", locals_to_params(locals()))
  File "/Users/neel/miniconda3/envs/webarena/lib/python3.10/site-packages/playwright/_impl/_connection.py", line 61, in send
    return await self._connection.wrap_api_call(
  File "/Users/neel/miniconda3/envs/webarena/lib/python3.10/site-packages/playwright/_impl/_connection.py", line 482, in wrap_api_call
    return await cb()
  File "/Users/neel/miniconda3/envs/webarena/lib/python3.10/site-packages/playwright/_impl/_connection.py", line 97, in inner_send
    result = next(iter(done)).result()
playwright._impl._api_types.Error: net::ERR_INTERNET_DISCONNECTED at http://ec2-3-131-244-37.us-east-2.compute.amazonaws.com:7770/
=========================== logs ===========================
navigating to "http://ec2-3-131-244-37.us-east-2.compute.amazonaws.com:7770/", waiting until "load"
============================================================
